<?xml version="1.0" ?>

<mujoco>
    <default>
        <default class="visual">
            <geom contype="0" conaffinity="0"/>
        </default>

        <default class="collision">
            <geom contype="1" conaffinity="1" friction=".6 0.005 0.0001"/>
        </default>
    </default>

    <!--  -->

    <body name="frank_robot_link_0" euler="1.57079632679 0 0">
        <geom class="visual" type="mesh" mesh="frank_robot_link_0_mesh" material="frank_robot_grey"/>
        <geom class="collision" type="mesh" mesh="frank_robot_link_0_mesh" material="frank_robot_grey"/>
        <!-- [E+09] -> Ixx="0.02626" Iyy="0.02671" Izz="0.00267" Ixy="-0.000006653998" Ixz="-0.001777" Iyz="-0.000023799371" -->
        <!-- [mm] cx="-0.014355" cy="0.040144" cz="-0.084033" -->
        <!-- [mm] offset_x="0" offset_y="0" offset_z="0" -->
        <inertial pos="-0.014355 0.040144 -0.084033" mass="1.961261" fullinertia="0.02626 0.02671 0.00267 -0.000006653998 -0.001777 -0.000023799371"/>

        <body name="frank_robot_link_1" pos="0 0.080 0.0">
            <geom class="visual" type="mesh" mesh="frank_robot_link_1_mesh" material="frank_robot_grey" pos="0 -0.080 0"/>
            <joint name="frank_robot_joint_1" axis="0 1 0" limited="true" range="-1.57079632679 1.57079632679"/>
            <!-- [E+09] -> Ixx="0.1943" Iyy="0.2875" Izz="0.1062" Ixy="-0.000004700255" Ixz="0.000011807009" Iyz="0.01948" -->
            <!-- [mm] cx="0.000007" cy="0.093989" cz="-0.03259" -->
            <!-- [mm] offset_x="0.0" offset_y="0.080" offset_z="0" -->
            <inertial pos="0.000007 0.013989 -0.03259" mass="11.74576" fullinertia="0.1943 0.2875 0.1062 -0.000004700255 0.000011807009 0.01948"/>

            <body name="frank_robot_link_2" pos="0 0.0751502092 -0.287331693">
                <geom class="visual" type="mesh" mesh="frank_robot_link_2_mesh" material="frank_robot_grey" pos="0 -0.1551502092 0.287331693"/>
                <joint name="frank_robot_joint_2" axis="1 0 0" limited="true" range="-1.57079632679 1.57079632679"/>
                <!-- [E+09] -> Ixx="0.3434" Iyy="0.02273" Izz="0.3578" Ixy="0.000" Ixz="0.000" Iyz="-0.0007620" -->
                <!-- [mm] cx="0.000058" cy="0.555149" cz="-0.286422" -->
                <!-- [mm] offset_x="0.0" offset_y="0.0751502092+0.080" offset_z="-0.287331693" -->
                <inertial pos="0.000058 0.3999987908 0.000909693" mass="4.169373" fullinertia="0.3434 0.02273 0.3578 0.000 0.000 -0.0007620"/>

                <body name="frank_robot_link_3" pos="0 0.800 0">
                    <geom class="visual" type="mesh" mesh="frank_robot_link_3_mesh" material="frank_robot_grey" pos="0 -0.9551502092 0.287331693"/>
                    <joint name="frank_robot_joint_3" axis="1 0 0" limited="true" range="-3.14 3.14"/>
                    <!-- [E+09] -> Ixx="0.4276" Iyy="0.005724" Izz="0.4266" Ixy="0.000024494682" Ixz="0.000000785316" Iyz="0.000003445672" -->
                    <!-- [mm] cx="0.000084" cy="1.355131" cz="-0.270238" -->
                    <!-- [mm] offset_x="0.000084" offset_y="0.0751502092+0.080+0.800" offset_z="-0.287331693" -->
                    <inertial pos="0.000064 0.399980791 0.017093693" mass="4.012871" fullinertia="0.4276 0.005724 0.4266 0.000024494682 0.000000785316 0.000003445672"/>

                    <body name="frank_robot_link_4" pos="0 0.8 0">
                        <geom class="visual" type="mesh" mesh="frank_robot_link_4_mesh" material="frank_robot_grey" pos="0 -1.7551502092 0.287331693"/>
                        <joint name="frank_robot_joint_4" axis="1 0 0" limited="true" range="-3.14 3.14"/>
                        <!-- [E+09] -> Ixx="0.03450" Iyy="0.004685" Izz="0.03257" Ixy="0.000003314724" Ixz="-0.000000127309" Iyz="0.001170" -->
                        <!-- [mm] cx="0.062876" cy="1.904191" cz="-0.306072" -->
                        <!-- [mm] offset_x="0" offset_y="0.0751502092+0.080+0.80+0.80" offset_z="-0.287331693" -->
                        <inertial pos="0.062882 0.0683407908 -0.007205307" mass="3.231165" fullinertia="0.03450 0.004685 0.03257 0.000003314724 -0.000000127309 0.001170"/>

                        <body name="frank_robot_ee" pos="0.0628881 0.3165 -0.0225">
                            <geom type="capsule" fromto="0 0 -0.001 0 0 0.001" size="0.001" rgba="0.15 0.15 0.15 1"/>
                            <site name="ee" rgba="0 0 0 1" pos="0 0 0"/>
                        </body>
                    </body>
                </body>
            </body>
        </body>
    </body>
</mujoco>